Program.cs, output from example:

BEGIN FIRST EXAMPLE
ResourceSecond: DoSomething
ResourceFirst: DoSomething

Unhandled Exception:
System.Exception: ResourceFirst DoSomething Exception!!!
  at TryWithResourcesC.ResourceFirst.DoSomething () [0x0001a] in /home/gustavo/github/CSharpForFun/Allgemeines/Try-With-Resources-C#/Try-With-Resources-C#/Program.cs:49
  at TryWithResourcesC.MainClass.Main (System.String[] args) [0x00029] in /home/gustavo/github/CSharpForFun/Allgemeines/Try-With-Resources-C#/Try-With-Resources-C#/Program.cs:20
I am the Dispose of ResourceSecond

Unhandled Exception:
System.Exception: ResourceSecond Dispose Exception!!!
  at TryWithResourcesC.ResourceSecond.Dispose () [0x0001a] in /home/gustavo/github/CSharpForFun/Allgemeines/Try-With-Resources-C#/Try-With-Resources-C#/Program.cs:72
  at TryWithResourcesC.MainClass.Main (System.String[] args) [0x0003b] in /home/gustavo/github/CSharpForFun/Allgemeines/Try-With-Resources-C#/Try-With-Resources-C#/Program.cs:17
I am the Dispose of ResourceFirst

Unhandled Exception:
System.Exception: ResourceFirst Dispose Exception!!!
  at TryWithResourcesC.ResourceFirst.Dispose () [0x0001a] in /home/gustavo/github/CSharpForFun/Allgemeines/Try-With-Resources-C#/Try-With-Resources-C#/Program.cs:56
  at TryWithResourcesC.MainClass.Main (System.String[] args) [0x0004d] in /home/gustavo/github/CSharpForFun/Allgemeines/Try-With-Resources-C#/Try-With-Resources-C#/Program.cs:16
[ERROR] FATAL UNHANDLED EXCEPTION: System.Exception: ResourceFirst Dispose Exception!!!
  at TryWithResourcesC.ResourceFirst.Dispose () [0x0001a] in /home/gustavo/github/CSharpForFun/Allgemeines/Try-With-Resources-C#/Try-With-Resources-C#/Program.cs:56
  at TryWithResourcesC.MainClass.Main (System.String[] args) [0x0004d] in /home/gustavo/github/CSharpForFun/Allgemeines/Try-With-Resources-C#/Try-With-Resources-C#/Program.cs:16



So, it is worse than Java because you can not see easily the hidden exceptions.
As in Java it keeps running the Dispose methods even if some of them throw exception!!!

SO, THE BEST WAY TO CLOSE DEVICES IN C# IS USING THE using statement!!!!!
OTHERWISE YOU ARE GOING TO WRITE LOADS OF CODE IF YOU WANT TO DO THE SAME!!!!



using (ResourceFirst resourceOne = new ResourceFirst())
using (ResourceSecond resourceTwo = new ResourceSecond())
{
	resourceTwo.DoSomething();
	resourceOne.DoSomething();
}


using statement under the scenes:

The UnhandledException event handles uncaught exceptions thrown from the main UI thread.
The ThreadException event handles uncaught exceptions thrown from non-UI threads.
Application.ThreadException;
AppDomain.CurrentDomain.UnhandledException;

try {
	// AppDomain
	Program();
}
catch(Exception e)
{
	AppDomain.CurrentDomain.UnhandledException = e;
}

if (AppDomain.CurrentDomain.UnhandledException != null)
{
	Console.WriteLine("[ERROR] FATAL UNHANDLED EXCEPTION: {0}", e.ToString());
}



Program()
{
	ResourceFirst resourceOne = new ResourceFirst()
	try{
		ResourceSecond resourceSecond = new ResourceSecond()
		resourceOne.DoSomething();
		resourceSecond.DoSomehting();
	}
	// When debuggin this catch exists. Does it exist when running without debug?
	// I guess, it will not exist but not sure.
	catch(Exception e)
	{
		Console.WriteLine("Unhandled Exception:");
		Console.WriteLine(e.ToString());
		throw e;
	}
	finally
	{
		if (resourceSecond != null)
		{
			try {
				resourceSecond.Dispose();
			}
			// When debuggin this catch exists. Does it exist when running without debug?
			// I guess, it will not exist but not sure.
			catch(Exception e)
			{
				Console.WriteLine("Unhandled Exception:");
				Console.WriteLine(e.ToString());
				throw e;
			}
			finally
			{
				resourceOne.Dispose();
			}
		}
		else
		{
			try {
				resourceOne.Dispose();
			}
			// When debuggin this catch exists. Does it exist when running without debug?
			// I guess, it will not exist but not sure.
			catch(Exception e)
			{
				Console.WriteLine("Unhandled Exception:");
				Console.WriteLine(e.ToString());
				throw e;
			}
		}
	}
}

IMHO the best way to close resources is by means of the using statement. In this way you close always the resources even
if there are exceptions. Besides we do not have to write loads of code to achieve it.


The old way:

MyResourceOne resourceOne;
MyResourceTwo resourceTwo;
try
{

}
finally
{
    if (resourceOne != null)
    {
        resourceOne.Dispose();
    }

    if (resourceTwo != null)
    {
        resourceTwo.Dispose();
    }
}

The problem with this way is, if resourceOne.Dispose() throws exception I am not going to call resourceTwo.Dispose() :(

BUT IF YOU WANT TO DO IT RIGHT (or at least as I think it is right) YOU MUST WRITE LOADS OF CODE, SO AT THE END IF YOU DO NOT USE
THE using statement THIS IS THE "BEST" SOLUTION (even if it is not perfect) BUT ALL DEPENDS ON YOUR CASE. With using statement you will
never have doubts :)  SO ALWAYS USE THE using statement (AFAIU)
